Workbook

Sheet RawData
A1: workload | B1: variant | C1: structure | D1: n | E1: time_ms | F1: steps | G1: moves | H1: comparisons
A2: W1 | B2: - | C2: DynamicArray | D2: 100 | E2: 0.2379 | F2: 10000 | G2: 0 | H2: 0
A3: W1 | B3: - | C3: LinkedList | D3: 100 | E3: 1.6813 | F3: 502068 | G3: 0 | H3: 0
A4: W2 | B4: - | C4: DynamicArray | D4: 100 | E4: 0.3444 | F4: 75238 | G4: 0 | H4: 75238
A5: W2 | B5: - | C5: LinkedList | D5: 100 | E5: 0.1234 | F5: 75238 | G5: 0 | H5: 75238
A6: W1 | B6: - | C6: DynamicArray | D6: 100 | E6: 0.4605 | F6: 10000 | G6: 0 | H6: 0
A7: W1 | B7: - | C7: LinkedList | D7: 100 | E7: 0.6445 | F7: 502068 | G7: 0 | H7: 0
A8: W2 | B8: - | C8: DynamicArray | D8: 100 | E8: 0.3111 | F8: 75238 | G8: 0 | H8: 75238
A9: W2 | B9: - | C9: LinkedList | D9: 100 | E9: 1.6528 | F9: 75238 | G9: 0 | H9: 75238
A10: W3 | B10: head | C10: DynamicArray | D10: 100 | E10: 3.7067 | F10: 1000 | G10: 1201920 | H10: 0
A11: W3 | B11: head | C11: LinkedList | D11: 100 | E11: 0.1133 | F11: 0 | G11: 2000 | H11: 0
A12: W3 | B12: middle | C12: DynamicArray | D12: 100 | E12: 0.1148 | F12: 1000 | G12: 1101920 | H12: 0
A13: W3 | B13: middle | C13: LinkedList | D13: 100 | E13: 0.1538 | F13: 100000 | G13: 3000 | H13: 0
... A41: W4 | B41: - | C41: MinHeap | D41: 100000 | E41: 9.5618 | F41: 6218250 | G41: 3387427 | H41: 3059125

Sheet ChartData
A1: W1 Random Access — Time (ms)
A2: n | B2: DynamicArray | C2: LinkedList
A3: 100 | B3: =SUMIFS(RawData!$E$2:$E$1000,RawData!$A$2:$A$1000,"W1",RawData!$B$2:$B$1000,"-",RawData!$C$2:$C$1000,"DynamicArray",RawData!$D$2:$D$1000,$A3) -> 0.6984 | C3: =SUMIFS(RawData!$E$2:$E$1000,RawData!$A$2:$A$1000,"W1",RawData!$B$2:$B$1000,"-",RawData!$C$2:$C$1000,"LinkedList",RawData!$D$2:$D$1000,$A3) -> 2.3258
A4: 1000 | B4: =SUMIFS(RawData!$E$2:$E$1000,RawData!$A$2:$A$1000,"W1",RawData!$B$2:$B$1000,"-",RawData!$C$2:$C$1000,"DynamicArray",RawData!$D$2:$D$1000,$A4) -> 0.1164 | C4: =SUMIFS(RawData!$E$2:$E$1000,RawData!$A$2:$A$1000,"W1",RawData!$B$2:$B$1000,"-",RawData!$C$2:$C$1000,"LinkedList",RawData!$D$2:$D$1000,$A4) -> 5.0848
A5: 10000 | B5: =SUMIFS(RawData!$E$2:$E$1000,RawData!$A$2:$A$1000,"W1",RawData!$B$2:$B$1000,"-",RawData!$C$2:$C$1000,"DynamicArray",RawData!$D$2:$D$1000,$A5) -> 0.1538 | C5: =SUMIFS(RawData!$E$2:$E$1000,RawData!$A$2:$A$1000,"W1",RawData!$B$2:$B$1000,"-",RawData!$C$2:$C$1000,"LinkedList",RawData!$D$2:$D$1000,$A5) -> 56.6775
A6: 100000 | B6: =SUMIFS(RawData!$E$2:$E$1000,RawData!$A$2:$A$1000,"W1",RawData!$B$2:$B$1000,"-",RawData!$C$2:$C$1000,"DynamicArray",RawData!$D$2:$D$1000,$A6) -> 0.1409 | C6: =SUMIFS(RawData!$E$2:$E$1000,RawData!$A$2:$A$1000,"W1",RawData!$B$2:$B$1000,"-",RawData!$C$2:$C$1000,"LinkedList",RawData!$D$2:$D$1000,$A6) -> 663.5636
A9: W1 Random Access — Steps / Moves / Comparisons
A10: n | B10: DynamicArray-steps | C10: DynamicArray-moves | D10: DynamicArray-comparisons | E10: LinkedList-steps | F10: LinkedList-moves | G10: LinkedList-comparisons
A11: 100 | B11: =SUMIFS(RawData!$F$2:$F$1000,RawData!$A$2:$A$1000,"W1",RawData!$B$2:$B$1000,"-",RawData!$C$2:$C$1000,"DynamicArray",RawData!$D$2:$D$1000,$A11) -> 20000 | C11: =SUMIFS(RawData!$G$2:$G$1000,RawData!$A$2:$A$1000,"W1",RawData!$B$2:$B$1000,"-",RawData!$C$2:$C$1000,"DynamicArray",RawData!$D$2:$D$1000,$A11) -> 0 | D11: =SUMIFS(RawData!$H$2:$H$1000,RawData!$A$2:$A$1000,"W1",RawData!$B$2:$B$1000,"-",RawData!$C$2:$C$1000,"DynamicArray",RawData!$D$2:$D$1000,$A11) -> 0 | E11: =SUMIFS(RawData!$F$2:$F$1000,RawData!$A$2:$A$1000,"W1",RawData!$B$2:$B$1000,"-",RawData!$C$2:$C$1000,"LinkedList",RawData!$D$2:$D$1000,$A11) -> 1004136 | F11: =SUMIFS(RawData!$G$2:$G$1000,RawData!$A$2:$A$1000,"W1",RawData!$B$2:$B$1000,"-",RawData!$C$2:$C$1000,"LinkedList",RawData!$D$2:$D$1000,$A11) -> 0 | G11: =SUMIFS(RawData!$H$2:$H$1000,RawData!$A$2:$A$1000,"W1",RawData!$B$2:$B$1000,"-",RawData!$C$2:$C$1000,"LinkedList",RawData!$D$2:$D$1000,$A11) -> 0
A12: 1000 | B12: =SUMIFS(RawData!$F$2:$F$1000,RawData!$A$2:$A$1000,"W1",RawData!$B$2:$B$1000,"-",RawData!$C$2:$C$1000,"DynamicArray",RawData!$D$2:$D$1000,$A12) -> 10000 | C12: =SUMIFS(RawData!$G$2:$G$1000,RawData!$A$2:$A$1000,"W1",RawData!$B$2:$B$1000,"-",RawData!$C$2:$C$1000,"DynamicArray",RawData!$D$2:$D$1000,$A12) -> 0 | D12: =SUMIFS(RawData!$H$2:$H$1000,RawData!$A$2:$A$1000,"W1",RawData!$B$2:$B$1000,"-",RawData!$C$2:$C$1000,"DynamicArray",RawData!$D$2:$D$1000,$A12) -> 0 | E12: =SUMIFS(RawData!$F$2:$F$1000,RawData!$A$2:$A$1000,"W1",RawData!$B$2:$B$1000,"-",RawData!$C$2:$C$1000,"LinkedList",RawData!$D$2:$D$1000,$A12) -> 4953268 | F12: =SUMIFS(RawData!$G$2:$G$1000,RawData!$A$2:$A$1000,"W1",RawData!$B$2:$B$1000,"-",RawData!$C$2:$C$1000,"LinkedList",RawData!$D$2:$D$1000,$A12) -> 0 | G12: =SUMIFS(RawData!$H$2:$H$1000,RawData!$A$2:$A$1000,"W1",RawData!$B$2:$B$1000,"-",RawData!$C$2:$C$1000,"LinkedList",RawData!$D$2:$D$1000,$A12) -> 0
A13: 10000 | B13: =SUMIFS(RawData!$F$2:$F$1000,RawData!$A$2:$A$1000,"W1",RawData!$B$2:$B$1000,"-",RawData!$C$2:$C$1000,"DynamicArray",RawData!$D$2:$D$1000,$A13) -> 10000 | C13: =SUMIFS(RawData!$G$2:$G$1000,RawData!$A$2:$A$1000,"W1",RawData!$B$2:$B$1000,"-",RawData!$C$2:$C$1000,"DynamicArray",RawData!$D$2:$D$1000,$A13) -> 0 | D13: =SUMIFS(RawData!$H$2:$H$1000,RawData!$A$2:$A$1000,"W1",RawData!$B$2:$B$1000,"-",RawData!$C$2:$C$1000,"DynamicArray",RawData!$D$2:$D$1000,$A13) -> 0 | E13: =SUMIFS(RawData!$F$2:$F$1000,RawData!$A$2:$A$1000,"W1",RawData!$B$2:$B$1000,"-",RawData!$C$2:$C$1000,"LinkedList",RawData!$D$2:$D$1000,$A13) -> 49618268 | F13: =SUMIFS(RawData!$G$2:$G$1000,RawData!$A$2:$A$1000,"W1",RawData!$B$2:$B$1000,"-",RawData!$C$2:$C$1000,"LinkedList",RawData!$D$2:$D$1000,$A13) -> 0 | G13: =SUMIFS(RawData!$H$2:$H$1000,RawData!$A$2:$A$1000,"W1",RawData!$B$2:$B$1000,"-",RawData!$C$2:$C$1000,"LinkedList",RawData!$D$2:$D$1000,$A13) -> 0
A14: 100000 | B14: =SUMIFS(RawData!$F$2:$F$1000,RawData!$A$2:$A$1000,"W1",RawData!$B$2:$B$1000,"-",RawData!$C$2:$C$1000,"DynamicArray",RawData!$D$2:$D$1000,$A14) -> 10000 | C14: =SUMIFS(RawData!$G$2:$G$1000,RawData!$A$2:$A$1000,"W1",RawData!$B$2:$B$1000,"-",RawData!$C$2:$C$1000,"DynamicArray",RawData!$D$2:$D$1000,$A14) -> 0 | D14: =SUMIFS(RawData!$H$2:$H$1000,RawData!$A$2:$A$1000,"W1",RawData!$B$2:$B$1000,"-",RawData!$C$2:$C$1000,"DynamicArray",RawData!$D$2:$D$1000,$A14) -> 0 | E14: =SUMIFS(RawData!$F$2:$F$1000,RawData!$A$2:$A$1000,"W1",RawData!$B$2:$B$1000,"-",RawData!$C$2:$C$1000,"LinkedList",RawData!$D$2:$D$1000,$A14) -> 493288268 | F14: =SUMIFS(RawData!$G$2:$G$1000,RawData!$A$2:$A$1000,"W1",RawData!$B$2:$B$1000,"-",RawData!$C$2:$C$1000,"LinkedList",RawData!$D$2:$D$1000,$A14) -> 0 | G14: =SUMIFS(RawData!$H$2:$H$1000,RawData!$A$2:$A$1000,"W1",RawData!$B$2:$B$1000,"-",RawData!$C$2:$C$1000,"LinkedList",RawData!$D$2:$D$1000,$A14) -> 0
A18: W2 Search — Time (ms)
A19: n | B19: DynamicArray | C19: LinkedList
A20: 100 | B20: =SUMIFS(RawData!$E$2:$E$1000,RawData!$A$2:$A$1000,"W2",RawData!$B$2:$B$1000,"-",RawData!$C$2:$C$1000,"DynamicArray",RawData!$D$2:$D$1000,$A20) -> 0.6555 | C20: =SUMIFS(RawData!$E$2:$E$1000,RawData!$A$2:$A$1000,"W2",RawData!$B$2:$B$1000,"-",RawData!$C$2:$C$1000,"LinkedList",RawData!$D$2:$D$1000,$A20) -> 1.7762
A21: 1000 | B21: =SUMIFS(RawData!$E$2:$E$1000,RawData!$A$2:$A$1000,"W2",RawData!$B$2:$B$1000,"-",RawData!$C$2:$C$1000,"DynamicArray",RawData!$D$2:$D$1000,$A21) -> 0.2453 | C21: =SUMIFS(RawData!$E$2:$E$1000,RawData!$A$2:$A$1000,"W2",RawData!$B$2:$B$1000,"-",RawData!$C$2:$C$1000,"LinkedList",RawData!$D$2:$D$1000,$A21) -> 1.1193
A22: 10000 | B22: =SUMIFS(RawData!$E$2:$E$1000,RawData!$A$2:$A$1000,"W2",RawData!$B$2:$B$1000,"-",RawData!$C$2:$C$1000,"DynamicArray",RawData!$D$2:$D$1000,$A22) -> 2.1792 | C22: =SUMIFS(RawData!$E$2:$E$1000,RawData!$A$2:$A$1000,"W2",RawData!$B$2:$B$1000,"-",RawData!$C$2:$C$1000,"LinkedList",RawData!$D$2:$D$1000,$A22) -> 12.1647
A23: 100000 | B23: =SUMIFS(RawData!$E$2:$E$1000,RawData!$A$2:$A$1000,"W2",RawData!$B$2:$B$1000,"-",RawData!$C$2:$C$1000,"DynamicArray",RawData!$D$2:$D$1000,$A23) -> 22.34 | C23: =SUMIFS(RawData!$E$2:$E$1000,RawData!$A$2:$A$1000,"W2",RawData!$B$2:$B$1000,"-",RawData!$C$2:$C$1000,"LinkedList",RawData!$D$2:$D$1000,$A23) -> 167.3
A26: W2 Search — Steps / Moves / Comparisons
A27: n | B27: DynamicArray-steps | C27: DynamicArray-moves | D27: DynamicArray-comparisons | E27: LinkedList-steps | F27: LinkedList-moves | G27: LinkedList-comparisons
A28: 100 | B28: =SUMIFS(RawData!$F$2:$F$1000,RawData!$A$2:$A$1000,"W2",RawData!$B$2:$B$1000,"-",RawData!$C$2:$C$1000,"DynamicArray",RawData!$D$2:$D$1000,$A28) -> 150476 | C28: =SUMIFS(RawData!$G$2:$G$1000,RawData!$A$2:$A$1000,"W2",RawData!$B$2:$B$1000,"-",RawData!$C$2:$C$1000,"DynamicArray",RawData!$D$2:$D$1000,$A28) -> 0 | D28: =SUMIFS(RawData!$H$2:$H$1000,RawData!$A$2:$A$1000,"W2",RawData!$B$2:$B$1000,"-",RawData!$C$2:$C$1000,"DynamicArray",RawData!$D$2:$D$1000,$A28) -> 150476 | E28: =SUMIFS(RawData!$F$2:$F$1000,RawData!$A$2:$A$1000,"W2",RawData!$B$2:$B$1000,"-",RawData!$C$2:$C$1000,"LinkedList",RawData!$D$2:$D$1000,$A28) -> 150476 | F28: =SUMIFS(RawData!$G$2:$G$1000,RawData!$A$2:$A$1000,"W2",RawData!$B$2:$B$1000,"-",RawData!$C$2:$C$1000,"LinkedList",RawData!$D$2:$D$1000,$A28) -> 0 | G28: =SUMIFS(RawData!$H$2:$H$1000,RawData!$A$2:$A$1000,"W2",RawData!$B$2:$B$1000,"-",RawData!$C$2:$C$1000,"LinkedList",RawData!$D$2:$D$1000,$A28) -> 150476
A29: 1000 | B29: =SUMIFS(RawData!$F$2:$F$1000,RawData!$A$2:$A$1000,"W2",RawData!$B$2:$B$1000,"-",RawData!$C$2:$C$1000,"DynamicArray",RawData!$D$2:$D$1000,$A29) -> 757638 | C29: =SUMIFS(RawData!$G$2:$G$1000,RawData!$A$2:$A$1000,"W2",RawData!$B$2:$B$1000,"-",RawData!$C$2:$C$1000,"DynamicArray",RawData!$D$2:$D$1000,$A29) -> 0 | D29: =SUMIFS(RawData!$H$2:$H$1000,RawData!$A$2:$A$1000,"W2",RawData!$B$2:$B$1000,"-",RawData!$C$2:$C$1000,"DynamicArray",RawData!$D$2:$D$1000,$A29) -> 757638 | E29: =SUMIFS(RawData!$F$2:$F$1000,RawData!$A$2:$A$1000,"W2",RawData!$B$2:$B$1000,"-",RawData!$C$2:$C$1000,"LinkedList",RawData!$D$2:$D$1000,$A29) -> 757638 | F29: =SUMIFS(RawData!$G$2:$G$1000,RawData!$A$2:$A$1000,"W2",RawData!$B$2:$B$1000,"-",RawData!$C$2:$C$1000,"LinkedList",RawData!$D$2:$D$1000,$A29) -> 0 | G29: =SUMIFS(RawData!$H$2:$H$1000,RawData!$A$2:$A$1000,"W2",RawData!$B$2:$B$1000,"-",RawData!$C$2:$C$1000,"LinkedList",RawData!$D$2:$D$1000,$A29) -> 757638
A30: 10000 | B30: =SUMIFS(RawData!$F$2:$F$1000,RawData!$A$2:$A$1000,"W2",RawData!$B$2:$B$1000,"-",RawData!$C$2:$C$1000,"DynamicArray",RawData!$D$2:$D$1000,$A30) -> 7489792 | C30: =SUMIFS(RawData!$G$2:$G$1000,RawData!$A$2:$A$1000,"W2",RawData!$B$2:$B$1000,"-",RawData!$C$2:$C$1000,"DynamicArray",RawData!$D$2:$D$1000,$A30) -> 0 | D30: =SUMIFS(RawData!$H$2:$H$1000,RawData!$A$2:$A$1000,"W2",RawData!$B$2:$B$1000,"-",RawData!$C$2:$C$1000,"DynamicArray",RawData!$D$2:$D$1000,$A30) -> 7489792 | E30: =SUMIFS(RawData!$F$2:$F$1000,RawData!$A$2:$A$1000,"W2",RawData!$B$2:$B$1000,"-",RawData!$C$2:$C$1000,"LinkedList",RawData!$D$2:$D$1000,$A30) -> 7489792 | F30: =SUMIFS(RawData!$G$2:$G$1000,RawData!$A$2:$A$1000,"W2",RawData!$B$2:$B$1000,"-",RawData!$C$2:$C$1000,"LinkedList",RawData!$D$2:$D$1000,$A30) -> 0 | G30: =SUMIFS(RawData!$H$2:$H$1000,RawData!$A$2:$A$1000,"W2",RawData!$B$2:$B$1000,"-",RawData!$C$2:$C$1000,"LinkedList",RawData!$D$2:$D$1000,$A30) -> 7489792
A31: 100000 | B31: =SUMIFS(RawData!$F$2:$F$1000,RawData!$A$2:$A$1000,"W2",RawData!$B$2:$B$1000,"-",RawData!$C$2:$C$1000,"DynamicArray",RawData!$D$2:$D$1000,$A31) -> 74253877 | C31: =SUMIFS(RawData!$G$2:$G$1000,RawData!$A$2:$A$1000,"W2",RawData!$B$2:$B$1000,"-",RawData!$C$2:$C$1000,"DynamicArray",RawData!$D$2:$D$1000,$A31) -> 0 | D31: =SUMIFS(RawData!$H$2:$H$1000,RawData!$A$2:$A$1000,"W2",RawData!$B$2:$B$1000,"-",RawData!$C$2:$C$1000,"DynamicArray",RawData!$D$2:$D$1000,$A31) -> 74253877 | E31: =SUMIFS(RawData!$F$2:$F$1000,RawData!$A$2:$A$1000,"W2",RawData!$B$2:$B$1000,"-",RawData!$C$2:$C$1000,"LinkedList",RawData!$D$2:$D$1000,$A31) -> 74253877 | F31: =SUMIFS(RawData!$G$2:$G$1000,RawData!$A$2:$A$1000,"W2",RawData!$B$2:$B$1000,"-",RawData!$C$2:$C$1000,"LinkedList",RawData!$D$2:$D$1000,$A31) -> 0 | G31: =SUMIFS(RawData!$H$2:$H$1000,RawData!$A$2:$A$1000,"W2",RawData!$B$2:$B$1000,"-",RawData!$C$2:$C$1000,"LinkedList",RawData!$D$2:$D$1000,$A31) -> 74253877
A35: W3 Insert&Remove (head) — Time (ms)
A36: n | B36: DynamicArray | C36: LinkedList
A37: 100 | B37: =SUMIFS(RawData!$E$2:$E$1000,RawData!$A$2:$A$1000,"W3",RawData!$B$2:$B$1000,"head",RawData!$C$2:$C$1000,"DynamicArray",RawData!$D$2:$D$1000,$A37) -> 3.7067 | C37: =SUMIFS(RawData!$E$2:$E$1000,RawData!$A$2:$A$1000,"W3",RawData!$B$2:$B$1000,"head",RawData!$C$2:$C$1000,"LinkedList",RawData!$D$2:$D$1000,$A37) -> 0.1133
A38: 1000 | B38: =SUMIFS(RawData!$E$2:$E$1000,RawData!$A$2:$A$1000,"W3",RawData!$B$2:$B$1000,"head",RawData!$C$2:$C$1000,"DynamicArray",RawData!$D$2:$D$1000,$A38) -> 0.1724 | C38: =SUMIFS(RawData!$E$2:$E$1000,RawData!$A$2:$A$1000,"W3",RawData!$B$2:$B$1000,"head",RawData!$C$2:$C$1000,"LinkedList",RawData!$D$2:$D$1000,$A38) -> 0.0259
A39: 10000 | B39: =SUMIFS(RawData!$E$2:$E$1000,RawData!$A$2:$A$1000,"W3",RawData!$B$2:$B$1000,"head",RawData!$C$2:$C$1000,"DynamicArray",RawData!$D$2:$D$1000,$A39) -> 0.8478 | C39: =SUMIFS(RawData!$E$2:$E$1000,RawData!$A$2:$A$1000,"W3",RawData!$B$2:$B$1000,"head",RawData!$C$2:$C$1000,"LinkedList",RawData!$D$2:$D$1000,$A39) -> 0.0395
A40: 100000 | B40: =SUMIFS(RawData!$E$2:$E$1000,RawData!$A$2:$A$1000,"W3",RawData!$B$2:$B$1000,"head",RawData!$C$2:$C$1000,"DynamicArray",RawData!$D$2:$D$1000,$A40) -> 11.1044 | C40: =SUMIFS(RawData!$E$2:$E$1000,RawData!$A$2:$A$1000,"W3",RawData!$B$2:$B$1000,"head",RawData!$C$2:$C$1000,"LinkedList",RawData!$D$2:$D$1000,$A40) -> 0.0463
A43: W3 Insert&Remove (head) — Steps / Moves / Comparisons
A44: n | B44: DynamicArray-steps | C44: DynamicArray-moves | D44: DynamicArray-comparisons | E44: LinkedList-steps | F44: LinkedList-moves | G44: LinkedList-comparisons
A45: 100 | B45: =SUMIFS(RawData!$F$2:$F$1000,RawData!$A$2:$A$1000,"W3",RawData!$B$2:$B$1000,"head",RawData!$C$2:$C$1000,"DynamicArray",RawData!$D$2:$D$1000,$A45) -> 1000 | C45: =SUMIFS(RawData!$G$2:$G$1000,RawData!$A$2:$A$1000,"W3",RawData!$B$2:$B$1000,"head",RawData!$C$2:$C$1000,"DynamicArray",RawData!$D$2:$D$1000,$A45) -> 1201920 | D45: =SUMIFS(RawData!$H$2:$H$1000,RawData!$A$2:$A$1000,"W3",RawData!$B$2:$B$1000,"head",RawData!$C$2:$C$1000,"DynamicArray",RawData!$D$2:$D$1000,$A45) -> 0 | E45: =SUMIFS(RawData!$F$2:$F$1000,RawData!$A$2:$A$1000,"W3",RawData!$B$2:$B$1000,"head",RawData!$C$2:$C$1000,"LinkedList",RawData!$D$2:$D$1000,$A45) -> 0 | F45: =SUMIFS(RawData!$G$2:$G$1000,RawData!$A$2:$A$1000,"W3",RawData!$B$2:$B$1000,"head",RawData!$C$2:$C$1000,"LinkedList",RawData!$D$2:$D$1000,$A45) -> 2000 | G45: =SUMIFS(RawData!$H$2:$H$1000,RawData!$A$2:$A$1000,"W3",RawData!$B$2:$B$1000,"head",RawData!$C$2:$C$1000,"LinkedList",RawData!$D$2:$D$1000,$A45) -> 0
A46: 1000 | B46: =SUMIFS(RawData!$F$2:$F$1000,RawData!$A$2:$A$1000,"W3",RawData!$B$2:$B$1000,"head",RawData!$C$2:$C$1000,"DynamicArray",RawData!$D$2:$D$1000,$A46) -> 1000 | C46: =SUMIFS(RawData!$G$2:$G$1000,RawData!$A$2:$A$1000,"W3",RawData!$B$2:$B$1000,"head",RawData!$C$2:$C$1000,"DynamicArray",RawData!$D$2:$D$1000,$A46) -> 3001024 | D46: =SUMIFS(RawData!$H$2:$H$1000,RawData!$A$2:$A$1000,"W3",RawData!$B$2:$B$1000,"head",RawData!$C$2:$C$1000,"DynamicArray",RawData!$D$2:$D$1000,$A46) -> 0 | E46: =SUMIFS(RawData!$F$2:$F$1000,RawData!$A$2:$A$1000,"W3",RawData!$B$2:$B$1000,"head",RawData!$C$2:$C$1000,"LinkedList",RawData!$D$2:$D$1000,$A46) -> 0 | F46: =SUMIFS(RawData!$G$2:$G$1000,RawData!$A$2:$A$1000,"W3",RawData!$B$2:$B$1000,"head",RawData!$C$2:$C$1000,"LinkedList",RawData!$D$2:$D$1000,$A46) -> 2000 | G46: =SUMIFS(RawData!$H$2:$H$1000,RawData!$A$2:$A$1000,"W3",RawData!$B$2:$B$1000,"head",RawData!$C$2:$C$1000,"LinkedList",RawData!$D$2:$D$1000,$A46) -> 0
A47: 10000 | B47: =SUMIFS(RawData!$F$2:$F$1000,RawData!$A$2:$A$1000,"W3",RawData!$B$2:$B$1000,"head",RawData!$C$2:$C$1000,"DynamicArray",RawData!$D$2:$D$1000,$A47) -> 1000 | C47: =SUMIFS(RawData!$G$2:$G$1000,RawData!$A$2:$A$1000,"W3",RawData!$B$2:$B$1000,"head",RawData!$C$2:$C$1000,"DynamicArray",RawData!$D$2:$D$1000,$A47) -> 21000000 | D47: =SUMIFS(RawData!$H$2:$H$1000,RawData!$A$2:$A$1000,"W3",RawData!$B$2:$B$1000,"head",RawData!$C$2:$C$1000,"DynamicArray",RawData!$D$2:$D$1000,$A47) -> 0 | E47: =SUMIFS(RawData!$F$2:$F$1000,RawData!$A$2:$A$1000,"W3",RawData!$B$2:$B$1000,"head",RawData!$C$2:$C$1000,"LinkedList",RawData!$D$2:$D$1000,$A47) -> 0 | F47: =SUMIFS(RawData!$G$2:$G$1000,RawData!$A$2:$A$1000,"W3",RawData!$B$2:$B$1000,"head",RawData!$C$2:$C$1000,"LinkedList",RawData!$D$2:$D$1000,$A47) -> 2000 | G47: =SUMIFS(RawData!$H$2:$H$1000,RawData!$A$2:$A$1000,"W3",RawData!$B$2:$B$1000,"head",RawData!$C$2:$C$1000,"LinkedList",RawData!$D$2:$D$1000,$A47) -> 0
A48: 100000 | B48: =SUMIFS(RawData!$F$2:$F$1000,RawData!$A$2:$A$1000,"W3",RawData!$B$2:$B$1000,"head",RawData!$C$2:$C$1000,"DynamicArray",RawData!$D$2:$D$1000,$A48) -> 1000 | C48: =SUMIFS(RawData!$G$2:$G$1000,RawData!$A$2:$A$1000,"W3",RawData!$B$2:$B$1000,"head",RawData!$C$2:$C$1000,"DynamicArray",RawData!$D$2:$D$1000,$A48) -> 201000000 | D48: =SUMIFS(RawData!$H$2:$H$1000,RawData!$A$2:$A$1000,"W3",RawData!$B$2:$B$1000,"head",RawData!$C$2:$C$1000,"DynamicArray",RawData!$D$2:$D$1000,$A48) -> 0 | E48: =SUMIFS(RawData!$F$2:$F$1000,RawData!$A$2:$A$1000,"W3",RawData!$B$2:$B$1000,"head",RawData!$C$2:$C$1000,"LinkedList",RawData!$D$2:$D$1000,$A48) -> 0 | F48: =SUMIFS(RawData!$G$2:$G$1000,RawData!$A$2:$A$1000,"W3",RawData!$B$2:$B$1000,"head",RawData!$C$2:$C$1000,"LinkedList",RawData!$D$2:$D$1000,$A48) -> 2000 | G48: =SUMIFS(RawData!$H$2:$H$1000,RawData!$A$2:$A$1000,"W3",RawData!$B$2:$B$1000,"head",RawData!$C$2:$C$1000,"LinkedList",RawData!$D$2:$D$1000,$A48) -> 0
A52: W3 Insert&Remove (middle) — Time (ms)
A53: n | B53: DynamicArray | C53: LinkedList
A54: 100 | B54: =SUMIFS(RawData!$E$2:$E$1000,RawData!$A$2:$A$1000,"W3",RawData!$B$2:$B$1000,"middle",RawData!$C$2:$C$1000,"DynamicArray",RawData!$D$2:$D$1000,$A54) -> 0.1148 | C54: =SUMIFS(RawData!$E$2:$E$1000,RawData!$A$2:$A$1000,"W3",RawData!$B$2:$B$1000,"middle",RawData!$C$2:$C$1000,"LinkedList",RawData!$D$2:$D$1000,$A54) -> 0.1538
A55: 1000 | B55: =SUMIFS(RawData!$E$2:$E$1000,RawData!$A$2:$A$1000,"W3",RawData!$B$2:$B$1000,"middle",RawData!$C$2:$C$1000,"DynamicArray",RawData!$D$2:$D$1000,$A55) -> 0.1288 | C55: =SUMIFS(RawData!$E$2:$E$1000,RawData!$A$2:$A$1000,"W3",RawData!$B$2:$B$1000,"middle",RawData!$C$2:$C$1000,"LinkedList",RawData!$D$2:$D$1000,$A55) -> 1.1145
...

Sheet w1_time

Sheet w1_metrics

Sheet w2_time

Sheet w2_metrics

Sheet w3_head_time

Sheet w3_head_metrics

Sheet w3_middle_time

Sheet w3_middle_metrics

Sheet w4_time

Sheet w4_metrics
